<?xml version="1.0"?>
<robot name="r3_robot">

  <material name="blue">
      <color rgba="0 0 0.8 1.0"/>
  </material>

  <material name="green">
      <color rgba="0 0.8 0 1.0"/>
  </material>

  <link name="world" />

  <link name="base_link">
    <visual>
      <geometry>
        <box size="0.2 0.2 0.02"/>
      </geometry>
      <origin xyz="0 0 -0.01"/>
      <material name="blue"/>
    </visual>
  </link>

<link name="link_1">
    <visual>
      <geometry>
        <box size="1.1 0.1 0.1"/>
      </geometry>
      <origin xyz="0.5 0 0.05"/>
      <material name="blue"/>
    </visual>
    <collision>
      <geometry>
        <box size="1.1 0.1 0.1"/>
      </geometry>
      <origin xyz="0.5 0 0.05"/>
    </collision>
  </link>

  <link name="link_2">
    <visual>
      <geometry>
        <box size="1.1 0.1 0.1"/>
      </geometry>
      <origin xyz="0.5 0 -0.05"/>
      <material name="blue"/>
    </visual>
    <collision>
      <geometry>
        <box size="1.1 0.1 0.1"/>
      </geometry>
      <origin xyz="0.5 0 -0.05"/>
    </collision>
  </link>

  <link name="link_3">
    <visual>
      <geometry>
        <box size="1.1 0.1 0.1"/>
      </geometry>
      <origin xyz="0.5 0 0.05"/>
      <material name="blue"/>
    </visual>
    <collision>
      <geometry>
        <box size="1.1 0.1 0.1"/>
      </geometry>
      <origin xyz="0.5 0 0.05"/>
    </collision>
  </link>

<link name="flange" />

<link name="tool">
    <visual>
      <geometry>
        <box size="0.2 0.05 0.05"/>
      </geometry>
      <origin xyz="0.1 0 0"/>
      <material name="green"/>
    </visual>
    <collision>
      <geometry>
        <box size="0.2 0.05 0.05"/>
      </geometry>
      <origin xyz="0.1 0 0"/>
    </collision>
  </link>

<link name="tool0" />

<joint name="world_to_base_link" type="fixed">
    <parent link="world"/>
    <child link="base_link"/>
</joint>

<joint name="base_link_link_1" type="revolute">
    <axis xyz="0 0 1"/>
    <limit effort="1000.0" lower="-1.5" upper="1.5" velocity="0.5"/>
    <parent link="base_link"/>
    <child link="link_1"/>
    <origin xyz="0 0 0"/>
</joint>

<joint name="link_1_link_2" type="revolute">
    <axis xyz="0 0 1"/>
    <limit effort="1000.0" lower="-1.5" upper="1.5" velocity="0.5"/>
    <parent link="link_1"/>
    <child link="link_2"/>
    <origin xyz="1 0 0"/>
</joint>

<joint name="link_2_link_3" type="revolute">
    <axis xyz="0 0 1"/>
    <limit effort="1000.0" lower="-1.5" upper="1.5" velocity="0.5"/>
    <parent link="link_2"/>
    <child link="link_3"/>
    <origin xyz="1 0 0"/>
</joint>

<joint name="link_3_to_flange" type="fixed">
    <parent link="link_3"/>
    <child link="flange"/>
    <origin xyz="1 0 0"/>
</joint>

<joint name="flange_to_tool" type="fixed">
    <parent link="flange"/>
    <child link="tool"/>
</joint>

<joint name="tool_to_tool0" type="fixed">
    <parent link="tool"/>
    <child link="tool0"/>
    <origin xyz="0.2 0 0"/>
</joint>

</robot>
